Workbook

Sheet KS
B2: 2022 | C2: 2023 | D2: 2024 | E2: 2025 | K2: (단위 : 원)
B3: 제 24 기 | C3: 제 25 기 | D3: 제 26 기 | E3: 제27기 | G3: 구 분 | H3: 2022 | I3: 2023 | J3: 2024 | K3: 2025
A4: 영 업 수 익 | B4: 8031651241233 | C4: 8588656501947 | D4: 10210184320220 | E4: 15715186906021 | G4: 영업수지* | H4: =B25-B23 -> 1108840026058 | I4: =C25-C23 -> 920178061478 | J4: =D25-D23 -> 1604621014870 | K4: =E25+E23 -> 2038439013887 | L4: >> 재무회계 영업수지 (관리회계와 상이)
A5: 1. 수수료수익 | B5: 879728724977 | C5: 841325606195 | D5: 981147868497 | E5: 1326643915441 | G5: 영업이익 | H5: =B25 -> 645745222154 | I5: =C25 -> 472385960719 | J5: =D25 -> 1024732993797 | K5: =E25 -> 1325457775596 | L5: >> 재무회계 영업이익 (관리회계와 상이)
A6: 2. 당기손익-공정가치측정금융상품 관련이익 | B6: 1422472224381 | C6: 1919236994116 | D6: 1825903144451 | E6: 3307057873640 | G6: 순이익 | H6: =B30 -> 493104211865 | I6: =C30 -> 338377541866 | J6: =D30 -> 815077919836 | K6: =E30 -> 1099404053545
A7: 3. 파생상품 관련이익 | B7: 3708606911147 | C7: 3616795370404 | D7: 4852810045985 | E7: 7937394374279
A8: 4. 기타포괄손익-공정가치측정금융상품 관련이익 | B8: 25548530300 | C8: 37451395449 | D8: 27969134650 | E8: 36242955725
A9: 5. 상각후원가측정금융상품 관련이익 | C9: 540141698 | D9: 122383378 | E9: 30000000 | G9: (백만원화) | K9: (단위 : 백만원)
A10: 6. 이자수익 | B10: 709816280534 | C10: 1105280269530 | D10: 1095474457058 | E10: 1217412708435 | G10: 구 분 | H10: 2022 | I10: 2023 | J10: 2024 | K10: =K3 -> 2025
A11: 유효이자율 적용 이자수익 | B11: 483275123308 | C11: 668886499916 | D11: 650108129741 | E11: 714901901221 | G11: 영업수지* | H11: =H4/1000000 -> 1108840 | I11: =I4/1000000 -> 920178.06 | J11: =J4/1000000 -> 1604621 | K11: =K4/1000000 -> 2038439 | L11: >> 재무회계 영업수지 (관리회계와 상이)
A12: 당기손익-공정가치측정금융자산 이자수익 | B12: 226541157226 | C12: 436393769614 | D12: 445366327317 | E12: 502510807214 | G12: 영업이익 | H12: =H5/1000000 -> 645745.22 | I12: =I5/1000000 -> 472385.96 | J12: =J5/1000000 -> 1024733 | K12: =K5/1000000 -> 1325457.8 | L12: >> 재무회계 영업이익 (관리회계와 상이)
A13: 7. 외환거래이익 | B13: 1278156442125 | C13: 1043885464452 | D13: 1419860612305 | E13: 1880351711978 | G13: 순이익 | H13: =H6/1000000 -> 493104.21 | I13: =I6/1000000 -> 338377.54 | J13: =J6/1000000 -> 815077.92 | K13: =K6/1000000 -> 1099404.1
A14: 8. 기타의영업수익 | B14: 7322127769 | C14: 24141260103 | D14: 6896673896 | E14: 10053366523
A15: 영 업 비 용 | B15: -7385906019079 | C15: -8116270541228 | D15: -9185451326423 | E15: 14389729130425
A16: 1. 수수료비용 | B16: -224688317037 | C16: -249990695402 | D16: -227849730025 | E16: 303931600722 | G16: (억원화) | K16: (단위 : 억원)
A17: 2. 당기손익-공정가치측정금융상품 관련손실 | B17: -1348863021981 | C17: -1660298354651 | D17: -1476017425255 | E17: 2785413688235 | G17: 구 분 | H17: 2022 | I17: 2023 | J17: 2024 | K17: =K10 -> 2025
A18: 3. 파생상품 관련손실 | B18: -3837601010236 | C18: -3374457410698 | D18: -4564939597569 | E18: 7925593273712 | G18: 영업수지* | H18: =H4/100000000 -> 11088.4 | I18: =I4/100000000 -> 9201.7806 | J18: =J4/100000000 -> 16046.21 | K18: =K4/100000000 -> 20384.39 | L18: >> 재무회계 영업수지 (관리회계와 상이)
A19: 4. 기타포괄손익-공정가치측정금융상품 관련손실 | B19: -5247189 | E19: 0 | G19: 영업이익 | H19: =H5/100000000 -> 6457.4522 | I19: =I5/100000000 -> 4723.8596 | J19: =J5/100000000 -> 10247.33 | K19: =K5/100000000 -> 13254.578 | L19: >> 재무회계 영업이익 (관리회계와 상이)
A20: 5. 상각후원가측정금융상품 관련손실 | B20: -907229490 | C20: -82340999 | D20: -1898727299 | E20: 676665730 | G20: 순이익 | H20: =H6/100000000 -> 4931.0421 | I20: =I6/100000000 -> 3383.7754 | J20: =J6/100000000 -> 8150.7792 | K20: =K6/100000000 -> 10994.041
A21: 6. 이자비용 | B21: -310981629362 | C21: -648557180716 | D21: -698139339796 | E21: 721922735178
A22: 7. 외환거래손실 | B22: -1136752314674 | C22: -1044447844063 | D22: -1493206313264 | E22: 1777644756877 | G22: (*) 영업이익+판관비
A23: 8. 판매비와관리비 | B23: -463094803904 | C23: -447792100759 | D23: -579888021073 | E23: 712981238291
A24: 9. 기타의영업비용 | B24: -63012445206 | C24: -690644613940 | D24: -143512172142 | E24: 161565171680
A25: 영 업 이 익 | B25: 645745222154 | C25: 472385960719 | D25: 1024732993797 | E25: 1325457775596
A26: 영 업 외 수 익 | B26: 65691968380 | C26: 63236147839 | D26: 92308586087 | E26: 165912440744
A27: 영 업 외 비 용 | B27: -48126082087 | C27: -84697552521 | D27: -26762775119 | E27: 34344324775
A28: 법인세비용차감전순이익 | B28: 663311108447 | C28: 450924556037 | D28: 1090278804765 | E28: 1457025891565
A29: 법 인 세 비 용 | B29: -170206896582 | C29: -112547014171 | D29: -275200884929 | E29: 357621838020
A30: 당 기 순 이 익 | B30: 493104211865 | C30: 338377541866 | D30: 815077919836 | E30: 1099404053545
A31: 기타포괄손익 | B31: -28325664217 | C31: -9437326203 | D31: 52675473546 | E31: 251969054090
A32: 1. 후속적으로 당기손익으로 재분류되는 항목
A33: 기타포괄손익-공정가치측정금융자산평가손익(채무상품) | B33: -223583000 | C33: 60363062 | E33: 0
A34: 2. 당기손익으로 재분류되지 않는 항목
A35: 기타포괄손익-공정가치측정금융자산평가손익(지분상품) | B35: -10368095014 | C35: 20456013929 | D35: 49635140766 | E35: 246242312041
A36: 당기손익-공정가치측정금융부채평가손익(신용위험조정) | B36: -20815970328 | C36: -29742303556 | D36: 3843698552 | E36: 5694226649
A37: 확정급여제도의 재측정요소 | B37: 3081984125 | C37: -211399638 | D37: -803365772 | E37: 32515400
A38: 총포괄손익 | B38: 464778547648 | C38: 328940215663 | D38: 867753393382 | E38: 1351373107635
A39: 주당이익
A40: 보통주기본주당이익 (단위 : 원) | B40: 17410 | C40: 12020 | D40: 30527 | E40: 43815
A41: 보통주희석주당이익 (단위 : 원) | B41: 16025 | C41: 11624 | D41: 27874 | E41: 41524
...

Sheet KAM
C2: 2022 | E2: 2023 | G2: 2024 | I2: 2025 | P2: (단위 : 원)
A3: 과 목 | B3: 주석 | C3: 제 35(전)기 | E3: 제 36(전)기 | G3: 제 37(당)기 | I3: 제 38(당)기 | L3: 구 분 | M3: 2022 | N3: 2023 | O3: 2024 | P3: 2025
A4: 영업수익 | D4: 90024688867 | F4: 81322396664 | H4: 85841969094 | J4: 125108643301 | L4: 영업수익* | M4: =D4-C11 -> 80624359062 | N4: =F4-E11 -> 79368867734 | O4: =H4-G11 -> 84954285588 | P4: =+J4-I11 -> 121656798234
A5: 수수료수익 | B5: 20 | C5: 80070484408 | E5: 71422299196 | G5: 77621748695 | I5: 92094289073 | L5: 영업이익 | M5: =D14 -> 27255369498 | N5: =F14 -> 22712705287 | O5: =H14 -> 22867230743 | P5: =+J14 -> 50049029913
A6: 유가증권평가 및 처분이익 | B6: 21 | C6: 6156609286 | E6: 6876488815 | G6: 4742261310 | I6: 21679315487 | L6: 순이익 | M6: =D19 -> 19466981535 | N6: =F19 -> 19325767712 | O6: =H19 -> 17648989053 | P6: =+J19 -> 46222786546
A7: 이자수익 | B7: 22 | C7: 187788067 | E7: 242127335 | G7: 512517915 | I7: 217361503
A8: 기타영업수익 | B8: 24 | C8: 3609807106 | E8: 2781481318 | G8: 2965441174 | I8: 11117677238
A9: 영업비용 | D9: 62769319369 | F9: 58609691377 | H9: 62974738351 | J9: 75059613388 | L9: (백만원화) | P9: (단위 : 백만원)
A10: 수수료비용 | B10: 20 | C10: 7506187426 | E10: 7279265886 | G10: 7821790900 | I10: 8174497849 | L10: 구 분 | M10: 2022 | N10: 2023 | O10: 2024 | P10: 2025
A11: 유가증권평가 및 처분손실 | B11: 21 | C11: 9400329805 | E11: 1953528930 | G11: 887683506 | I11: 3451845067 | L11: 영업수익* | M11: =M4/1000000 -> 80624.359 | N11: =N4/1000000 -> 79368.868 | O11: =O4/1000000 -> 84954.286 | P11: =P4/1000000 -> 121656.8
A12: 일반관리비 | B12: 23 | C12: 44817538891 | E12: 49038338278 | G12: 53813829604 | I12: 61783148657 | L12: 영업이익 | M12: =M5/1000000 -> 27255.369 | N12: =N5/1000000 -> 22712.705 | O12: =O5/1000000 -> 22867.231 | P12: =P5/1000000 -> 50049.03
A13: 기타영업비용 | B13: 24 | C13: 1045263247 | E13: 338558283 | G13: 451434341 | I13: 1650121815 | L13: 순이익 | M13: =M6/1000000 -> 19466.982 | N13: =N6/1000000 -> 19325.768 | O13: =O6/1000000 -> 17648.989 | P13: =P6/1000000 -> 46222.787
A14: 영업이익 | D14: 27255369498 | F14: 22712705287 | H14: 22867230743 | J14: 50049029913
A15: 영업외수익 | B15: 25 | D15: 22261213 | F15: 1592293956 | H15: 8404082983 | J15: 17614434136
A16: 영업외비용 | B16: 25 | D16: 921524607 | F16: 293828638 | H16: 8816472342 | J16: 7900557242 | L16: (억원화) | P16: (단위 : 억원)
A17: 법인세비용차감전순이익 | D17: 26356106104 | F17: 24011170605 | H17: 22454841384 | J17: 59762906807 | L17: 구 분 | M17: 2022 | N17: 2023 | O17: 2024 | P17: 2025
A18: 법인세비용 | B18: 26 | D18: 6889124569 | F18: 4685402893 | H18: 4805852331 | J18: 13540120261 | L18: 영업수익* | M18: =M4/100000000 -> 806.24359 | N18: =N4/100000000 -> 793.68868 | O18: =O4/100000000 -> 849.54286 | P18: =P4/100000000 -> 1216.568
A19: 당기순이익 | D19: 19466981535 | F19: 19325767712 | H19: 17648989053 | J19: 46222786546 | L19: 영업이익 | M19: =M5/100000000 -> 272.55369 | N19: =N5/100000000 -> 227.12705 | O19: =O5/100000000 -> 228.67231 | P19: =P5/100000000 -> 500.4903
A20: 기타포괄손익 | D20: - | F20: - | H20: - | J20: - | L20: 순이익 | M20: =M6/100000000 -> 194.66982 | N20: =N6/100000000 -> 193.25768 | O20: =O6/100000000 -> 176.48989 | P20: =P6/100000000 -> 462.22787
A21: 당기총포괄손익 | D21: 19466981535 | F21: 19325767712 | H21: 17648989053 | J21: 46222786546
A22: 기본 및 희석주당이익 | B22: 19 | D22: 1371 | F22: 1361 | H22: 1243 | J22: 3254 | L22: (*) 영업수익-유가증권평가 및 처분손실

Sheet KSB
B2: 2022 | E2: 2023 | G2: 2024 | I2: 2025 | P2: (단위 : 원)
A3: 과 목 | B3: 제 41(전)기 | D3: 과 목 | E3: 제 42(전) 기 | G3: 제 43(당) 기 | I3: 제 44(당) 기 | L3: 구 분 | M3: 2022 | N3: 2023 | O3: 2024 | P3: 2025
A4: I. 영업수익 | C4: 171813414397 | D4: I. 영업수익 | F4: 199614627616 | H4: 174076555068 | J4: 156512893610 | L4: 영업수지* | M4: =C48+B40+B35+B45 -> 99866895037 | N4: =F49+E42+E37-E26 -> 73763656287 | O4: =H49+G42+G37-G26 -> 80251967564 | P4: =J49+I42+I37-I26 -> 84411385657
A5: 1. 이자수익(주석22) | B5: 152478449892 | D5: 1. 이자수익(주석24) | E5: 181112888270 | G5: 153531997479 | L5: 영업이익 | M5: =+C48 -> 45606719545 | N5: =+F49 -> 2525654435 | O5: =+H49 -> 4831371254 | P5: =+J49 -> 5273028827
A6: (1) 예치금이자 | B6: 6907092877 | D6: (1) 예치금이자 | E6: 16329843150 | G6: 10743683981 | L6: 순이익 | M6: =+C62 -> 35263625567 | N6: =+F63 -> 2986363323 | O6: =+H63 -> 3900853084 | P6: =+J63 -> 3406591396
A7: (2) 매도가능증권이자 | B7: 636686396 | D7: (2) 단기매매증권이자 | E7: - | G7: 374863
A8: (3) 대출채권이자 | B8: 144756315461 | D8: (3) 매도가능증권이자 | E8: 1079714241 | G8: 655809328
A9: (4) 기타이자수익 | B9: 178355158 | D9: (4) 대출채권이자 | E9: 163523889653 | G9: 141986154336 | L9: (백만원화) | P9: (단위 : 백만원)
A10: 2. 유가증권평가 및 처분이익 | B10: 250157223 | D10: (5) 기타이자수익 | E10: 179441226 | G10: 145974971 | L10: 구 분 | M10: 2022 | N10: 2023 | O10: 2024 | P10: 2025
A11: (1) 단기매매증권평가이익 | B11: - | D11: 2. 유가증권평가 및 처분이익 | E11: 5665856744 | G11: 3450495288 | L11: 영업수지* | M11: =M4/1000000 -> 99866.895 | N11: =N4/1000000 -> 73763.656 | O11: =O4/1000000 -> 80251.968 | P11: =P4/1000000 -> 84411.386
A12: (2) 단기매매증권처분이익 | B12: 56060000 | D12: (1) 단기매매증권평가이익 | E12: 2688832300 | G12: 16510904 | L12: 영업이익 | M12: =M5/1000000 -> 45606.72 | N12: =N5/1000000 -> 2525.6544 | O12: =O5/1000000 -> 4831.3713 | P12: =P5/1000000 -> 5273.0288
A13: (3) 매도가능증권처분이익 | B13: 194097223 | D13: (2) 단기매매증권처분이익 | E13: 1854284690 | G13: 2527336955 | L13: 순이익 | M13: =M6/1000000 -> 35263.626 | N13: =N6/1000000 -> 2986.3633 | O13: =O6/1000000 -> 3900.8531 | P13: =P6/1000000 -> 3406.5914
A14: 3. 대출채권평가및처분이익 | B14: 1131558234 | D14: (3) 매도가능증권처분이익 | E14: 1122739754 | G14: 906647429
A15: (1) 대출채권매매이익(주석6) | B15: 1131558234 | D15: 3. 대출채권평가 및 매매이익 | E15: 4940869726 | G15: 7799998502
A16: 4. 수수료수익 | B16: 9408197393 | D16: (1) 대출채권매매이익(주석7) | E16: 4940869726 | G16: 7799998502 | L16: (억원화) | P16: (단위 : 억원)
A17: (1) 송금수입수수료 | B17: 55096600 | D17: 4. 수수료수익 | E17: 4273703646 | G17: 4433905132 | L17: 구 분 | M17: 2022 | N17: 2023 | O17: 2024 | P17: 2025
A18: (2) 중도해지수입수수료 | B18: 3184702420 | D18: (1) 송금수입수수료 | E18: 51044200 | G18: 42557800 | L18: 영업수지* | M18: =M4/100000000 -> 998.66895 | N18: =N4/100000000 -> 737.63656 | O18: =O4/100000000 -> 802.51968 | P18: =P4/100000000 -> 844.11386
A19: (3) 대리사무취급수입수수료 | B19: 900000 | D19: (2) 중도해지수입수수료 | E19: 2399341194 | G19: 2308986610 | L19: 영업이익 | M19: =M5/100000000 -> 456.0672 | N19: =N5/100000000 -> 25.256544 | O19: =O5/100000000 -> 48.313713 | P19: =P5/100000000 -> 52.730288
A20: (4) 기타수입수수료 | B20: 6167498373 | D20: (3) 대리사무취급수입수수료 | E20: 100000 | G20: - | L20: 순이익 | M20: =M6/100000000 -> 352.63626 | N20: =N6/100000000 -> 29.863633 | O20: =O6/100000000 -> 39.008531 | P20: =P6/100000000 -> 34.065914
A21: 5. 배당금수익 | B21: 8545051655 | D21: (4) 기타수입수수료 | E21: 1823218252 | G21: 2082360722
A22: (1) 단기매매주식배당금 | B22: 828463500 | D22: 5. 배당금수익 | E22: 2984022310 | G22: 4068798299 | L22: (*) 영업이익 + 판관비 + 대손상각비 (+ 미사용약정충당금전입액 or -미사용약정충당금환입액)
A23: (2) 매도가능증권배당금 | B23: 7716588155 | D23: (1) 단기매매증권배당금 | E23: 722719250 | G23: 371776450
A24: 6. 기타영업이익 | B24: - | D24: (2) 매도가능증권배당금 | E24: 2261303060 | G24: 3697021849
A25: (1) 미사용약정충당부채환입액(주석12,13) | B25: - | D25: 6. 기타영업이익 | E25: 637286920 | G25: 791360368 | I25: 119305396
A26: II. 영업비용 | C26: 126206694852 | D26: (1) 미사용약정충당부채환입액(주석14,15) | E26: 637286920 | G26: 754445111 | I26: 102249158
A27: 1. 이자비용(주석22) | B27: 54152600781 | D27: (2) 기타자산대손충당금환입액 | E27: - | G27: 36915257
A28: (1) 예수금이자 | B28: 54007801293 | D28: II. 영업비용 | F28: 197088973181 | H28: 169245183814
A29: (2) 기타이자비용 | B29: 144799488 | D29: 1. 이자비용(주석24) | E29: 107482251854 | G29: 75657189826
A30: 2. 유가증권평가 및 처분손실 | B30: 6339352288 | D30: (1) 예수금이자 | E30: 107317179058 | G30: 75533267256
A31: (1) 단기매매증권평가손실 | B31: 6139619070 | D31: (2) 기타이자비용 | E31: 165072796 | G31: 123922570
A32: (2) 단기매매증권처분손실 | B32: 24288000 | D32: 2. 유가증권평가 및 처분손실 | E32: 1225967 | G32: 1829625958
A33: (3) 매도가능증권처분손실 | B33: 175445218 | D33: (1) 단기매매증권처분손실 | E33: 932104 | G33: 4224200
A34: 3. 대출채권평가 및 처분손실 | B34: 26566899474 | D34: (2) 매도가능증권처분손실 | E34: 293863 | G34: 597758
A35: (1) 대손상각비(주석6) | B35: 26529020203 | D35: (3) 매도가능증권손상차손(주석6) | E35: - | G35: 1824804000
A36: (2) 대출채권매매손실(주석6) | B36: 37879271 | D36: 3. 대출채권평가 및 매매손실 | E36: 51428018896 | G36: 53631461335
A37: 4. 수수료비용 | B37: 2702329222 | D37: (1) 대손상각비(주석7) | E37: 46803189306 | G37: 50428944312 | I37: 51708243345
A38: (1) 송금지급수수료 | B38: 34973700 | D38: (2) 대출채권매매손실(주석7) | E38: 4624829590 | G38: 3202517023
A39: (2) 기타지급수수료 | B39: 2667355522 | D39: 4. 수수료비용 | E39: 2345175588 | G39: 2416560471
A40: 5. 판매비와관리비(주석19) | B40: 25830947641 | D40: (1) 송금지급수수료 | E40: 19702600 | G40: 175500
A41: (1) 인건비 | B41: 12295002317 | D41: (2) 기타지급수수료 | E41: 2325472988 | G41: 2416384971
...

Sheet KYSB
B2: 2022 | E2: 2023 | G2: 2024 | I2: 2025 | P2: (단위 : 원)
A3: 과 목 | B3: 제 53(전) 기 | D3: 과 목 | E3: 제 54(전) 기 | G3: 제 55(당) 기 | I3: 제 56(당) 기 | L3: 구 분 | M3: 2022 | N3: 2023 | O3: 2024 | P3: 2025
A4: Ⅰ.영업수익 | C4: 116128543240 | D4: Ⅰ.영업수익 | F4: 147044638123 | H4: 145662697720 | J4: 122035565548 | L4: 영업수지* | M4: =C45+B43+B37+B32 -> 68305342372 | N4: =+F48+E46+E40+E36 -> 51616426796 | O4: =+H48+G40+G36-G26 -> 63740057724 | P4: =+J48+I40+I36-I26 -> 60292332247
A5: 1.이자수익(주석23) | B5: 102022477888 | D5: 1.이자수익(주석23) | E5: 136884029316 | G5: 128254447916 | L5: 영업이익 | M5: =C45 -> 26866042513 | N5: =F48 -> -5020427129 | O5: =H48 -> -34467315255 | P5: =J48 -> -9667560426
A6: (1) 예치금이자 | B6: 4218722734 | D6: (1) 예치금이자 | E6: 9641321273 | G6: 6041078422 | L6: 순이익 | M6: =C56 -> 20829032482 | N6: =F60 -> -3048464436 | O6: =H60 -> -27089060188 | P6: =J60 -> -6697613883
A7: (2) 당기손익인식증권이자 | B7: - | D7: (2) 단기매매증권이자 | E7: 322522985 | G7: 1887809680
A8: (3) 매도가능증권이자 | B8: - | D8: (3) 매도가능증권이자 | E8: 509116825 | G8: 427787470
A9: (4) 만기보유증권이자 | B9: 279511646 | D9: (4) 만기보유증권이자 | E9: 500116353 | G9: 491504741 | L9: (백만원화) | P9: (단위 : 백만원)
A10: (5) 대출채권이자 | B10: 97316970306 | D10: (5) 대출채권이자 | E10: 125648401271 | G10: 119184755347 | L10: 구 분 | M10: 2022 | N10: 2023 | O10: 2024 | P10: 2025
A11: (6) 기타이자수익 | B11: 207273202 | D11: (6) 기타이자수익 | E11: 262550609 | G11: 221512256 | L11: 영업수지* | M11: =M4/1000000 -> 68305.342 | N11: =N4/1000000 -> 51616.427 | O11: =O4/1000000 -> 63740.058 | P11: =P4/1000000 -> 60292.332
A12: 2.유가증권평가 및 처분이익 | B12: 7623975750 | D12: 2.유가증권평가 및 처분이익 | E12: 939022714 | G12: 2297407451 | L12: 영업이익 | M12: =M5/1000000 -> 26866.043 | N12: =N5/1000000 -> -5020.4271 | O12: =O5/1000000 -> -34467.315 | P12: =P5/1000000 -> -9667.5604
A13: (1) 당기손익인식증권매매이익 | B13: - | D13: (1) 단기매매증권매매이익 | E13: 258190077 | G13: 534306249 | L13: 순이익 | M13: =M6/1000000 -> 20829.032 | N13: =N6/1000000 -> -3048.4644 | O13: =O6/1000000 -> -27089.06 | P13: =P6/1000000 -> -6697.6139
A14: (2) 당기손익인식증권평가이익 | B14: - | D14: (2) 단기매매증권평가이익 | E14: 680832637 | G14: 1650072262
A15: (3) 매도가능증권처분이익 | B15: 7623975750 | D15: (3) 매도가능증권처분이익 | E15: - | G15: 113028940
A16: 3.대출채권평가 및 처분이익(주석7) | B16: 152509099 | D16: 3.대출채권평가 및 처분이익(주석7) | E16: 4098504810 | G16: 9171303603 | L16: (억원화) | P16: (단위 : 억원)
A17: (1) 대출채권매매이익 | B17: 152509099 | D17: (1) 대출채권매매이익 | E17: 4098504810 | G17: 9171303603 | L17: 구 분 | M17: 2022 | N17: 2023 | O17: 2024 | P17: 2025
A18: 4.수수료수익 | B18: 4523104452 | D18: 4.수수료수익 | E18: 3495024589 | G18: 3252076136 | L18: 영업수지* | M18: =M4/100000000 -> 683.05342 | N18: =N4/100000000 -> 516.16427 | O18: =O4/100000000 -> 637.40058 | P18: =P4/100000000 -> 602.92332
A19: (1) 송금수입수수료 | B19: 25451800 | D19: (1) 송금수입수수료 | E19: 31817000 | G19: 14443300 | L19: 영업이익 | M19: =M5/100000000 -> 268.66043 | N19: =N5/100000000 -> -50.204271 | O19: =O5/100000000 -> -344.67315 | P19: =P5/100000000 -> -96.675604
A20: (2) 대리사무취급수임수수료 | B20: 60707 | D20: (2) 대리사무취급수임수수료 | E20: 221925 | G20: 31413 | L20: 순이익 | M20: =M6/100000000 -> 208.29032 | N20: =N6/100000000 -> -30.484644 | O20: =O6/100000000 -> -270.8906 | P20: =P6/100000000 -> -66.976139
A21: (3) 중도해지수입수수료 | B21: 1619353986 | D21: (3) 중도해지수입수수료 | E21: 1135884031 | G21: 1395819969
A22: (4) 기타수입수수료 | B22: 2878237959 | D22: (4) 기타수입수수료 | E22: 2327101633 | G22: 1841781454 | L22: (*) 영업이익 + 판관비 + 대손상각비 (+ 미사용약정충당금전입액 or -미사용약정충당금환입액)
A23: 5.배당금수익 | B23: 1806476051 | D23: 5.배당금수익 | E23: 1628056694 | G23: 1406290138
A24: (1) 매도가능증권배당금수익 | B24: 1806476051 | D24: (1) 매도가능증권배당금수익 | E24: 1628056694 | G24: 1406290138
A25: Ⅱ.영업비용 | C25: 89262500727 | D25: 6.기타영업수익 | E25: - | G25: 1281172476
A26: 1.이자비용(주석23) | B26: 40160920162 | D26: (1) 미사용약정충당금환입 | E26: - | G26: 1221672483 | I26: 55374480
A27: (1) 예수금이자 | B27: 40023668002 | D27: (2) 기타충당부채환입 | E27: - | G27: 59499993
A28: (2) 기타이자비용 | B28: 137252160 | D28: Ⅱ.영업비용 | F28: 152065065252 | H28: 180130012975
A29: 2.유가증권평가 및 처분손실 | B29: - | D29: 1.이자비용(주석23) | E29: 84642482376 | G29: 69036485194
A30: (1) 당기손익인식증권매매손실 | B30: - | D30: (1) 예수금이자 | E30: 84469562733 | G30: 68900536639
A31: 3.대출채권평가 및 처분손실(주석7) | B31: 22476627181 | D31: (2) 기타이자비용 | E31: 172919643 | G31: 135948555
A32: (1) 대손상각비 | B32: 22468726089 | D32: 2.유가증권평가 및 처분손실 | E32: 245170 | G32: 174192186
A33: (2) 대출채권매매손실 | B33: 7901092 | D33: (1) 단기매매증권매매손실 | E33: 245170 | G33: 171161466
A34: 4.수수료비용 | B34: 1773551899 | D34: (2) 매도가능증권매매손실 | E34: - | G34: 3030720
A35: (1) 연체대출금회수수수료 | B35: 240400 | D35: 3.대출채권평가 및 처분손실(주석7) | E35: 37108429674 | G35: 78756538607
A36: (2) 기타지급수수료 | B36: 1773311499 | D36: (1) 대손상각비 | E36: 36553956250 | G36: 77642022405 | I36: 47302485826
A37: 5.판매비와관리비(주석17) | B37: 17914167631 | D37: (2) 대출채권매매손실 | E37: 554473424 | G37: 1114516202
A38: (1) 인건비 | B38: 9128416843 | D38: 4.수수료비용 | E38: 2185297721 | G38: 2249239685
A39: (2) 경비 | B39: 8785750788 | D39: (1) 기타지급수수료 | E39: 2185297721 | G39: 2249239685
A40: 6. 기타영업비용 | B40: 6937233854 | D40: 5.판매비와관리비(주석17) | E40: 19603533441 | G40: 21787023057 | I40: 22712781327
A41: (1) 예금보험료 | B41: 5797217000 | D41: (1) 인건비 | E41: 8565519196 | G41: 9341168294
...

Sheet KI
B2: 2022 | E2: 2023 | G2: 2024 | I2: 2025 | O2: (단위 : 원) | P2: (단위 : 원)
A3: 과 목 | B3: 제 24(전) 기 | D3: 과 목 | E3: 제 25(전)기 | G3: 제 26(당)기 | I3: 제 27(당)기 | L3: 구 분 | M3: 2022 | N3: 2023 | O3: 2024 | P3: 2025
A4: Ⅰ. 영업수익 | C4: 10233457170 | D4: Ⅰ. 영업수익 | F4: 15559485549 | H4: 19997147608 | J4: 30091251590 | L4: 영업수익* | M4: =C4-((B9-20000000)/2) -> 9857065924 | N4: =+F4-(E8/2) -> 1.464229e+10 | O4: =H4-(G8/2) -> 1.7299997e+10 | P4: =J4-(I8/2) -> 2.5507803e+10
A5: (1) 투자수익 | C5: 65000000 | D5: (1) 투자수익 | F5: - | H5: - | J5: 654040000 | L5: 영업이익 | M5: =C50 -> 2507822021 | N5: =F51 -> 3318567354 | O5: =H51 -> 6724939169 | P5: =J51 -> 14584158783
A6: 기타투자수익 | B6: 65000000 | D6: (2) 투자조합수익 | F6: 14991452717 | H6: 19438931720 | J6: 28983507951 | L6: 순이익 | M6: =C62 -> 1925162923 | N6: =F62 -> 2812002002 | O6: =H62 -> 5872859173 | P6: =J62 -> 11467157439
A7: (2) 투자조합수익 | C7: 10066863459 | D7: 조합관리보수(주석14) | E7: 9060214775 | G7: 8905516364 | I7: 8540342153
A8: 조합관리보수(주석14) | B8: 6517827584 | D8: 조합성과보수(주석14) | E8: 1834390409 | G8: 5394300259 | I8: 9166897129
A9: 조합성과보수(주석14) | B9: 772782492 | D9: 조합출자금처분이익 | E9: 4833333 | G9: 737 | L9: (백만원화) | O9: (단위 : 백만원) | P9: (단위 : 백만원)
A10: 조합출자금처분이익 | B10: - | D10: 조합지분법이익(주석3) | E10: 4092014200 | G10: 5139114360 | L10: 구 분 | M10: 2022 | N10: 2023 | O10: 2024 | P10: 2025
A11: 조합지분법이익(주석3) | B11: 2776253383 | D11: (3) 운용투자수익 | F11: - | H11: 31615 | L11: 영업수익* | M11: =M4/1000000 -> 9857.0659 | N11: =N4/1000000 -> 14642.29 | O11: =O4/1000000 -> 17299.997 | P11: =P4/1000000 -> 25507.803
A12: (3) 운용투자수익 | C12: 14359250 | D12: 운용투자주식처분이익 | E12: - | G12: 317 | L12: 영업이익 | M12: =M5/1000000 -> 2507.822 | N12: =N5/1000000 -> 3318.5674 | O12: =O5/1000000 -> 6724.9392 | P12: =P5/1000000 -> 14584.159
A13: 운용투자주식처분이익 | B13: 14359250 | D13: 운용투자사채처분이익 | E13: - | G13: 31298 | L13: 순이익 | M13: =M6/1000000 -> 1925.1629 | N13: =N6/1000000 -> 2812.002 | O13: =O6/1000000 -> 5872.8592 | P13: =P6/1000000 -> 11467.157
A14: (4) 기타의영업수익 | C14: 87234461 | D14: (4) 기타의영업수익 | F14: 568032832 | H14: 558184273
A15: 이자수익(주석14) | B15: 87234461 | D15: 이자수익(주석14) | E15: 568032832 | G15: 464167052
A16: Ⅱ. 영업비용 | C16: 7725635149 | D16: 복구충당부채환입 | E16: - | G16: 94017221 | L16: (억원화) | O16: (단위 : 억원) | P16: (단위 : 억원)
A17: (1) 투자및금융비용 | C17: 2629102635 | D17: Ⅱ. 영업비용 | F17: 12240918195 | H17: 13272208439 | L17: 구 분 | M17: 2022 | N17: 2023 | O17: 2024 | P17: 2025
A18: 투자주식처분손실 | B18: - | D18: (1) 투자및금융비용 | F18: 5099369413 | H18: 3378480480 | L18: 영업수익* | M18: =M4/100000000 -> 98.570659 | N18: =N4/100000000 -> 146.4229 | O18: =O4/100000000 -> 172.99997 | P18: =P4/100000000 -> 255.07803
A19: 투자사채처분손실 | B19: - | D19: 투자주식처분손실 | E19: 10000 | G19: - | L19: 영업이익 | M19: =M5/100000000 -> 25.07822 | N19: =N5/100000000 -> 33.185674 | O19: =O5/100000000 -> 67.249392 | P19: =P5/100000000 -> 145.84159
A20: 조합출자금처분손실 | B20: - | D20: 투자사채처분손실 | E20: 1000 | G20: - | L20: 순이익 | M20: =M6/100000000 -> 19.251629 | N20: =N6/100000000 -> 28.12002 | O20: =O6/100000000 -> 58.728592 | P20: =P6/100000000 -> 114.67157
A21: 조합지분법손실(주석3) | B21: 2473985581 | D21: 조합출자금처분손실 | E21: 1033111373 | G21: 1077584019
A22: 이자비용(차입금이자) | B22: 117005690 | D22: 조합지분법손실(주석3) | E22: 3837380406 | G22: 2147358558 | L22: (*) 영업수익 - (조합성과보수/2)
A23: 이자비용 | B23: 38111364 | D23: 이자비용(차입금이자) | E23: 223483555 | G23: 150429639
A24: (2) 운용투자비용 | C24: 17336280 | D24: 이자비용 | E24: 5383079 | G24: 852
A25: 운용투자주식처분손실 | B25: - | D25: 복구충당부채전입 | E25: - | G25: 3107412
A26: 운용투자사채처분손실 | B26: 17336280 | D26: (2) 운용투자비용 | F26: 984502341 | H26: -
A27: (3)일반관리비(주석13) | C27: 5079196234 | D27: 운용투자주식처분손실 | E27: 911151096 | G27: -
A28: 급여 | B28: 2802665473 | D28: 운용투자사채처분손실 | E28: 73351245 | G28: -
A29: 퇴직급여(주석6) | B29: 283050000 | D29: (3)일반관리비(주석13) | F29: 6157046441 | H29: 9893727959 | J29: 12176740028
A30: 복리후생비 | B30: 399153580 | D30: 급여 | E30: 3843680097 | G30: 6361794197
A31: 여비교통비 | B31: 99862534 | D31: 퇴직급여(주석6) | E31: 312153250 | G31: 394188548
A32: 접대비 | B32: 213578583 | D32: 복리후생비 | E32: 359118607 | G32: 445580436
A33: 통신비 | B33: 29823660 | D33: 여비교통비 | E33: 56398510 | G33: 140852328
A34: 세금과공과 | B34: 139260298 | D34: 접대비 | E34: 277102511 | G34: 366008519
A35: 임차료(주석14) | B35: 478343790 | D35: 통신비 | E35: 33545726 | G35: 36855609
A36: 차량유지비 | B36: 123294195 | D36: 세금과공과 | E36: 76619440 | G36: 96405060
A37: 운반비 | B37: 2503300 | D37: 임차료(주석14) | E37: 485129114 | G37: 894008280
A38: 교육훈련비 | B38: 22323000 | D38: 차량유지비 | E38: 93531195 | G38: 119376069
A39: 도서인쇄비 | B39: 9360240 | D39: 운반비 | E39: 2137300 | G39: 2176200
A40: 소모품비 | B40: 11269137 | D40: 교육훈련비 | E40: 14121000 | G40: 28727850
A41: 지급수수료 | B41: 334584540 | D41: 도서인쇄비 | E41: 3490780 | G41: 6177680
...

Sheet KPE
C2: 2022 | E2: 2023 | G2: 2024 | I2: 2025 | P2: (단위 : 원)
A3: 과 목 | B3: 주 석 | C3: 제 6(전) 기 | E3: 제 7(전) 기 | G3: 제 8(당) 기 | I3: 제 9(당) 기 | L3: 구 분 | M3: 2022 | N3: 2023 | O3: 2024 | P3: 2025
A4: I. 영업수익 | D4: 5331338169 | F4: 12898710927 | H4: 8500814660 | J4: 7958643959 | L4: 영업수익 | M4: =D4 -> 5331338169 | N4: =F4 -> 12898710927 | O4: =H4 -> 8500814660 | P4: =J4 -> 7958643959
A5: 이자수익 | B5: 4 | C5: 146547290 | E5: 756101126 | G5: 667385393 | L5: 영업이익 | M5: =D17 -> -12696755960 | N5: =F17 -> 5089168801 | O5: =H17 -> -420649392 | P5: =+J17 -> 1200374774 | Q5: 당기손익-공정가치측정금융상품관련이익 4,21 786,860,935
A6: 당기손익-공정가치측정금융상품관련이익 | B6: 4,20 | C6: 70793080 | E6: 676194820 | G6: 786860935 | L6: 순이익 | M6: =D22 -> -11846037361 | N6: =F22 -> 5819063613 | O6: =H22 -> -1858925084 | P6: =+J22 -> 508331940 | Q6: 지분법적용주식처분이익 9 -
A7: 관리보수 | B7: 25 | C7: 3133013838 | E7: 3598150036 | G7: 3710459513 | Q7: 관리보수 27 3,710,459,513
A8: 성과보수 | B8: 25 | C8: 1283958568 | E8: 1225825593 | G8: 178048712 | Q8: 성과보수 27 - 178,048,712
A9: 지분법이익 | B9: 9 | C9: 697025393 | E9: 6642439352 | G9: 3158060107 | L9: (백만원화) | P9: (단위 : 백만원) | Q9: 지분법이익 9 2,253,348,316
A10: II. 영업비용 | D10: 18028094129 | F10: 7809542126 | H10: 8921464052 | J10: 6758269185 | L10: 구 분 | M10: 2022 | N10: 2023 | O10: 2024 | P10: 2025
A11: 당기손익-공정가치측정금융상품관련손실 | B11: 4,20 | C11: 62448176 | E11: 623031150 | G11: 272641300 | L11: 영업수익 | M11: =M4/1000000 -> 5331.3382 | N11: =N4/1000000 -> 12898.711 | O11: =O4/1000000 -> 8500.8147 | P11: =P4/1000000 -> 7958.644
A12: 지분법손실 | B12: 9 | C12: 1462702560 | E12: 2683778175 | G12: 4834406583 | L12: 영업이익 | M12: =M5/1000000 -> -12696.756 | N12: =N5/1000000 -> 5089.1688 | O12: =O5/1000000 -> -420.64939 | P12: =P5/1000000 -> 1200.3748
A13: 지분법적용주식처분손실 | B13: 9 | C13: 13027816866 | E13: 284711 | G13: 48377608 | L13: 순이익 | M13: =M6/1000000 -> -11846.037 | N13: =N6/1000000 -> 5819.0636 | O13: =O6/1000000 -> -1858.9251 | P13: =P6/1000000 -> 508.33194
A14: 지분법적용투자주식손상차손 | B14: 9 | C14: 87607191 | E14: 961717620 | G14: -
A15: 이자비용 | B15: 9 | C15: - | E15: 9990494 | G15: 87818382
A16: 일반관리비 | B16: 21 | C16: 3387519336 | E16: 3530739976 | G16: 3678220179 | L16: (억원화) | P16: (단위 : 억원)
A17: III. 영업이익(손실) | D17: -12696755960 | F17: 5089168801 | H17: -420649392 | J17: 1200374774 | L17: 구 분 | M17: 2022 | N17: 2023 | O17: 2024 | P17: 2025
A18: IV. 영업외수익 | B18: 21 | D18: 2119940 | F18: 12467905 | H18: 69644484 | L18: 영업수익 | M18: =M4/100000000 -> 53.313382 | N18: =N4/100000000 -> 128.98711 | O18: =O4/100000000 -> 85.008147 | P18: =P4/100000000 -> 79.58644
A19: V. 영업외비용 | B19: 21 | D19: 2885087 | F19: 78712233 | H19: 34152385 | L19: 영업이익 | M19: =M5/100000000 -> -126.96756 | N19: =N5/100000000 -> 50.891688 | O19: =O5/100000000 -> -4.2064939 | P19: =P5/100000000 -> 12.003748
A20: VI. 법인세비용차감전순이익(손실) | D20: -12697521107 | F20: 5022924473 | H20: -385157293 | L20: 순이익 | M20: =M6/100000000 -> -118.46037 | N20: =N6/100000000 -> 58.190636 | O20: =O6/100000000 -> -18.589251 | P20: =P6/100000000 -> 5.0833194
A21: VII. 법인세비용(수익) | B21: 22 | D21: -851483746 | F21: -796139140 | H21: 1473767791
A22: VIII. 당기순이익(손실) | D22: -11846037361 | F22: 5819063613 | H22: -1858925084 | J22: 508331940
A23: IX. 기타포괄손익 | D23: 31709698 | F23: -39776100 | H23: -37724329
A24: 1. 후속적으로 당기손익으로 재분류되지 않는 항목: | D24: 31709698 | F24: -39776100 | H24: -37724329
A25: 보험수리적손익 | C25: 31709698 | E25: -39776100 | G25: -37724329
A26: X. 총포괄이익(손실) | D26: -11814327663 | F26: 5779287513 | H26: -1896649413
A27: XI. 주당이익
A28: 기본주당이익(손실) | B28: 24 | D28: -1181 | F28: 578 | H28: -190

Sheet KC
B2: 2022 | C2: 2023 | D2: 2024 | E2: 2025 | K2: (단위 : 원)
B3: 제 5 기 | C3: 제 6 기 | D3: 제 7 기 | E3: 제 8 기 | G3: 구 분 | H3: 2022 | I3: 2023 | J3: 2024 | K3: 2025
A4: I. 영업수익 | B4: 139804268433 | C4: 167018523235 | D4: 207663908465 | E4: 249313558393 | G4: 영업수지* | H4: =+B22+B21+B19+B37-B38 -> 72646247979 | I4: =+C22+C21+C19+C37-C38 -> 57493259707 | J4: =+D22+D21+D19+D37-D38 -> 57707662050 | K4: =+E22+E21+E19+E37-E38 -> 94122419889
A5: 1. 이자수익 | B5: 93938482802 | C5: 113227506560 | D5: 130331946710 | G5: 영업이익 | H5: =B22 -> 43077642022 | I5: =C22 -> 33476983675 | J5: =D22 -> 40516306493 | K5: =E22 -> 73022150813
A6: (1) 상각후원가측정 금융상품 이자수익 | B6: 92675577562 | C6: 106693056628 | D6: 123714157115 | G6: 순이익 | H6: =B26 -> 31404547250 | I6: =C26 -> 25950665318 | J6: =D26 -> 29230307247 | K6: =E26 -> 55512815007
A7: (2) 당기손익-공정가치측정 금융상품 이자수익 | B7: 1262905240 | C7: 6534449932 | D7: 6617789595
A8: 2. 수수료수익 | B8: 12459081414 | C8: 12797284585 | D8: 18991233526
A9: 3. 당기손익-공정가치측정 금융상품 관련이익 | B9: 30518227074 | C9: 36933327730 | D9: 49474622182 | G9: (백만원화) | K9: (단위 : 백만원)
A10: 4. 지분법이익 | B10: 0 | C10: 1423073316 | D10: 1416287103 | G10: 구 분 | H10: 2022 | I10: 2023 | J10: 2024 | K10: 2025
A11: 5. 외환거래이익 | B11: 1185784933 | C11: 0 | D11: 0 | G11: 영업수지* | H11: =H4/1000000 -> 72646.248 | I11: =I4/1000000 -> 57493.26 | J11: =J4/1000000 -> 57707.662 | K11: =K4/1000000 -> 94122.42
A12: 6. 기타의영업수익 | B12: 1702692210 | C12: 2637331044 | D12: 7449818944 | G12: 영업이익 | H12: =H5/1000000 -> 43077.642 | I12: =I5/1000000 -> 33476.984 | J12: =J5/1000000 -> 40516.306 | K12: =K5/1000000 -> 73022.151
A13: II. 영업비용 | B13: 96726626411 | C13: 133541539560 | D13: 167147601972 | G13: 순이익 | H13: =H6/1000000 -> 31404.547 | I13: =I6/1000000 -> 25950.665 | J13: =J6/1000000 -> 29230.307 | K13: =K6/1000000 -> 55512.815
A14: 1. 이자비용 | B14: 52712289827 | C14: 92821727260 | D14: 120450911062
A15: 2. 수수료비용 | B15: 2136129926 | C15: 1905849234 | D15: 2339690313
A16: 3. 당기손익-공정가치측정 금융상품 관련손실 | B16: 8976471560 | C16: 10278591551 | D16: 14892211439 | G16: (억원화) | K16: (단위 : 억원)
A17: 4. 지분법손실 | B17: 515655436 | C17: 1893170150 | D17: 4825768175 | G17: 구 분 | H17: 2022 | I17: 2023 | J17: 2024 | K17: 2025
A18: 5. 외환거래손실 | B18: 1619561766 | C18: 1828277930 | D18: 7354002348 | G18: 영업수지* | H18: =H4/100000000 -> 726.46248 | I18: =I4/100000000 -> 574.9326 | J18: =J4/100000000 -> 577.07662 | K18: =K4/100000000 -> 941.2242
A19: 6. 신용손실충당금전입액 | B19: 16804950060 | C19: 13778226470 | D19: 4486866955 | E19: 3607556981 | G19: 영업이익 | H19: =H5/100000000 -> 430.77642 | I19: =I5/100000000 -> 334.76984 | J19: =J5/100000000 -> 405.16306 | K19: =K5/100000000 -> 730.22151
A20: 7. 기타의영업비용 | B20: 1474865939 | C20: 12921403 | D20: 13734078 | G20: 순이익 | H20: =H6/100000000 -> 314.04547 | I20: =I6/100000000 -> 259.50665 | J20: =J6/100000000 -> 292.30307 | K20: =K6/100000000 -> 555.12815
A21: 8. 판매비와관리비 | B21: 12486701897 | C21: 11022775562 | D21: 12784417602 | E21: 17667288095
A22: III. 영업이익 | B22: 43077642022 | C22: 33476983675 | D22: 40516306493 | E22: 73022150813 | G22: (*) 영업이익 + 판관비 + 신용손실충당금전입액 (+ 미사용약정충당부채전입액 or -미사용약정충당부채환입액)
A23: IV. 영업외손익 | B23: 76252675 | C23: -20025061 | D23: -80287093
A24: V. 법인세비용차감전순이익 | B24: 43153894697 | C24: 33456958614 | D24: 40436019400
A25: VI. 법인세비용 | B25: 11749347447 | C25: 7506293296 | D25: 11205712153
A26: VII. 당기순이익 | B26: 31404547250 | C26: 25950665318 | D26: 29230307247 | E26: 55512815007
A27: VIII. 기타포괄손익 | B27: 623348455 | C27: -781471522 | D27: -161850804
A28: 1. 후속적으로 당기손익으로 재분류되지 않는 항목
A29: 확정급여제도의 재측정요소 | B29: 134844376 | C29: -108766427 | D29: -128573874
A30: 2. 후속적으로 당기손익으로 재분류될 수 있는 항목
A31: 현금흐름위험회피평가손익 | B31: 488504079 | C31: -672705095 | D31: -33276930
A32: IX. 총포괄손익 | B32: 32027895705 | C32: 25169193796 | D32: 29068456443
A33: X. 주당이익
A34: 1. 기본 및 희석주당이익 (단위 : 원) | B34: 2855 | C34: 2289 | D34: 2436
A36: 주석16. 충당부채 (16-2) | B36: 2022 | C36: 2023 | D36: 2024 | E36: 2025
A37: 미사용약정충당부채 전입(+) | B37: 276954000
A38: 미사용약정충당부채 환입(-) | C38: 784726000 | D38: 79929000 | E38: 174576000

Sheet KFI(연결)
B2: 2022 | C2: 2023 | D2: 2024 | E2: 2025 | K2: (단위 : 원)
B3: 제 3 기 | C3: 제 4 기 | D3: 제 5 기 | E3: 제 6 기 | G3: 구 분 | H3: 2022 | I3: 2023 | J3: 2024 | K3: 2025
A4: 영업수익 | B4: 44156900563 | C4: 48747495391 | D4: 94320006447 | E4: 140426956266 | G4: 영업수익 | H4: =B4 -> 44156900563 | I4: =C4 -> 48747495391 | J4: =D4 -> 94320006447 | K4: =E4 -> 140426956266
A5: 수수료수익 | B5: 0 | C5: 666107769 | D5: 327546305 | G5: 영업이익 | H5: =B23 -> 12024422813 | I5: =C23 -> 10616428006 | J5: =D23 -> 16514190766 | K5: =E23 -> 25586295109
A6: 이자수익 | B6: 18534460170 | C6: 31960502492 | D6: 67971498630 | G6: 순이익 | H6: =B27 -> 10431809970 | I6: =C27 -> 7237975298 | J6: =D27 -> 13047100290 | K6: =E27 -> 20701199696
A7: 유효이자율적용이자수익 | B7: 18194950582 | C7: 30220747238 | D7: 64527904093
A8: 당기손익-공정가치 측정 금융자산 이자수익 | B8: 339509588 | C8: 1739755254 | D8: 3443594537
A9: 당기손익-공정가치측정금융자산관련이익 | B9: 2968940838 | C9: 9735319149 | D9: 8154631717 | G9: (백만원화) | K9: (단위 : 백만원)
A10: 상각후원가측정금융자산관련이익 | B10: 21259256677 | C10: 5564134593 | D10: 14037912337 | G10: 구 분 | H10: 2022 | I10: 2023 | J10: 2024 | K10: 2025
A11: 파생상품평가 및 거래이익 | B11: 1394242878 | C11: 252721476 | D11: 0 | G11: 영업수익 | H11: =H4/1000000 -> 44156.901 | I11: =I4/1000000 -> 48747.495 | J11: =J4/1000000 -> 94320.006 | K11: =K4/1000000 -> 140426.96
A12: 배당금수익 | B12: 0 | C12: 527300000 | D12: 668200000 | G12: 영업이익 | H12: =H5/1000000 -> 12024.423 | I12: =I5/1000000 -> 10616.428 | J12: =J5/1000000 -> 16514.191 | K12: =K5/1000000 -> 25586.295
A13: 기타영업수익 | B13: 0 | C13: 41409912 | D13: 3160217458 | G13: 순이익 | H13: =H6/1000000 -> 10431.81 | I13: =I6/1000000 -> 7237.9753 | J13: =J6/1000000 -> 13047.1 | K13: =K6/1000000 -> 20701.2
A14: 영업비용 | B14: 32132477750 | C14: 38131067385 | D14: 77805815681
A15: 수수료비용 | B15: 3278367474 | C15: 3205628616 | D15: 3917210698
A16: 이자비용 | B16: 9198301472 | C16: 17659067609 | D16: 42564429912 | G16: (억원화) | K16: (단위 : 억원)
A17: 당기손익-공정가치측정금융자산관련손실 | B17: 1386443714 | C17: 321808100 | D17: 1489111857 | G17: 구 분 | H17: 2022 | I17: 2023 | J17: 2024 | K17: 2025
A18: 상각후원가측정금융자산관련손실 | B18: 10356162529 | C18: 9075322670 | D18: 19646646372 | G18: 영업수익 | H18: =H4/100000000 -> 441.56901 | I18: =I4/100000000 -> 487.47495 | J18: =J4/100000000 -> 943.20006 | K18: =K4/100000000 -> 1404.2696
A19: 파생상품평가 및 거래손실 | B19: 175026095 | C19: 498798001 | D19: 448785870 | G19: 영업이익 | H19: =H5/100000000 -> 120.24423 | I19: =I5/100000000 -> 106.16428 | J19: =J5/100000000 -> 165.14191 | K19: =K5/100000000 -> 255.86295
A20: 외환거래손실 | B20: 1425600000 | C20: 0 | D20: 0 | G20: 순이익 | H20: =H6/100000000 -> 104.3181 | I20: =I6/100000000 -> 72.379753 | J20: =J6/100000000 -> 130.471 | K20: =K6/100000000 -> 207.012
A21: 기타영업비용 | B21: 72144128 | C21: 1004002766 | D21: 489553714
A22: 판매비와관리비 | B22: 6240432338 | C22: 6366439623 | D22: 9250077258
A23: 영업이익(손실) | B23: 12024422813 | C23: 10616428006 | D23: 16514190766 | E23: 25586295109
A24: 영업외비용 | B24: 22956306 | C24: 0 | D24: 0
A25: 법인세비용차감전순이익(손실) | B25: 12001466507 | C25: 10616428006 | D25: 16514190766
A26: 법인세비용(수익) | B26: 1569656537 | C26: 3378452708 | D26: 3467090476
A27: 당기순이익(손실) | B27: 10431809970 | C27: 7237975298 | D27: 13047100290 | E27: 20701199696
A28: 지배주주지분 | B28: 10431809970 | C28: 7237975298 | D28: 13047100290
A29: 비지배주주지분 | B29: 0 | C29: 0 | D29: 0
A30: 기타포괄손익 | B30: 31705920 | C30: -68110376 | D30: -88878486
A31: 확정급여제도의재측정요소 | B31: 31705920 | C31: -68110376 | D31: -88878486
A32: 총포괄손익 | B32: 10463515890 | C32: 7169864922 | D32: 12958221804
A33: 지배주주비분 | B33: 10463515890 | C33: 7169864922 | D33: 12958221804
A34: 비지배주주지분 | B34: 0 | C34: 0 | D34: 0

Sheet 금융_통합
J2: (단위 : 백만원)
B3: 구분 | C3: 영업수지/영업수익 | G3: 영업이익 | L3: 구분 | M3: 영업수지/영업수익 산식
C4: 2022 | D4: 2023 | E4: 2024 | F4: 2025 | G4: 2022 | H4: 2023 | I4: 2024 | J4: 2025
B5: KS(관리) | C5: 1048318.9 | D5: 856805.28 | E5: 1592671 | F5: 2093349 | G5: 623564 | H5: 443354 | I5: 1059922 | J5: 1421928 | L5: KS(관리) | M5: 22/23년 영업이익 보고 시 관리 -> 재무로 변경
B6: KS* | C6: =KS!H11 -> 1108840 | D6: =KS!I11 -> 920178.06 | E6: =KS!J11 -> 1604621 | F6: =KS!K11 -> 2038439 | G6: =KS!H12 -> 645745.22 | H6: =KS!I12 -> 472385.96 | I6: =KS!J12 -> 1024733 | J6: =KS!K12 -> 1325457.8 | L6: KS | M6: 영업이익 + 판관비
B7: KAM | C7: =KAM!M11 -> 80624.359 | D7: =KAM!N11 -> 79368.868 | E7: =KAM!O11 -> 84954.286 | F7: =KAM!P11 -> 121656.8 | G7: =KAM!M12 -> 27255.369 | H7: =KAM!N12 -> 22712.705 | I7: =KAM!O12 -> 22867.231 | J7: =KAM!P12 -> 50049.03 | L7: KAM | M7: 영업수익 - 유가증권평가 및 처분손실
B8: KSB* | C8: =KSB!M11 -> 99866.895 | D8: =KSB!N11 -> 73763.656 | E8: =KSB!O11 -> 80251.968 | F8: =KSB!P11 -> 84411.386 | G8: =KSB!M12 -> 45606.72 | H8: =KSB!N12 -> 2525.6544 | I8: =KSB!O12 -> 4831.3713 | J8: =KSB!P12 -> 5273.0288 | L8: KSB | M8: 영업이익 + 판관비 + 대손상각비 (+ 미사용약정충당금전입액 or -미사용약정충당금환입액)
B9: KYSB* | C9: =KYSB!M11 -> 68305.342 | D9: =KYSB!N11 -> 51616.427 | E9: =KYSB!O11 -> 63740.058 | F9: =KYSB!P11 -> 60292.332 | G9: =KYSB!M12 -> 26866.043 | H9: =KYSB!N12 -> -5020.4271 | I9: =KYSB!O12 -> -34467.315 | J9: =KYSB!P12 -> -9667.5604 | L9: KYSB | M9: 영업이익 + 판관비 + 대손상각비 (+ 미사용약정충당금전입액 or -미사용약정충당금환입액)
B10: KI | C10: =KI!M11 -> 9857.0659 | D10: =KI!N11 -> 14642.29 | E10: =KI!O11 -> 17299.997 | F10: =KI!P11 -> 25507.803 | G10: =KI!M12 -> 2507.822 | H10: =KI!N12 -> 3318.5674 | I10: =KI!O12 -> 6724.9392 | J10: =KI!P12 -> 14584.159 | L10: KI | M10: 영업수익 - (조합성과보수/2)
B11: KPE | C11: =KPE!M11 -> 5331.3382 | D11: =KPE!N11 -> 12898.711 | E11: =KPE!O11 -> 8500.8147 | F11: =KPE!P11 -> 7958.644 | G11: =KPE!M12 -> -12696.756 | H11: =KPE!N12 -> 5089.1688 | I11: =KPE!O12 -> -420.64939 | J11: =KPE!P12 -> 1200.3748 | L11: KPE
B12: KC* | C12: =KC!H11 -> 72646.248 | D12: =KC!I11 -> 57493.26 | E12: =KC!J11 -> 57707.662 | F12: =KC!K11 -> 94122.42 | G12: =KC!H12 -> 43077.642 | H12: =KC!I12 -> 33476.984 | I12: =KC!J12 -> 40516.306 | J12: =KC!K12 -> 73022.151 | L12: KC | M12: 영업이익 + 판관비 + 신용손실충당금전입액 (+ 미사용약정충당부채전입액 or -미사용약정충당부채환입액)
B13: KFI(연결) | C13: ='KFI(연결)'!H11 -> 44156.901 | D13: ='KFI(연결)'!I11 -> 48747.495 | E13: ='KFI(연결)'!J11 -> 94320.006 | F13: ='KFI(연결)'!K11 -> 140426.96 | G13: ='KFI(연결)'!H12 -> 12024.423 | H13: ='KFI(연결)'!I12 -> 10616.428 | I13: ='KFI(연결)'!J12 -> 16514.191 | J13: ='KFI(연결)'!K12 -> 25586.295 | L13: KFI(연결)
A14: KS(관리) | B14: 합계 | C14: =SUM(C7:C13,C5) -> 1429107 | D14: =SUM(D7:D13,D5) -> 1195336 | E14: =SUM(E7:E13,E5) -> 1999445.8 | F14: =SUM(F7:F13,F5) -> 2627725.3 | G14: =SUM(G7:G13,G5) -> 768205.26 | H14: =SUM(H7:H13,H5) -> 516073.08 | I14: =SUM(I7:I13,I5) -> 1116488.1 | J14: =SUM(J7:J13,J5) -> 1581975.5
B15: (*)영업수지
J16: (단위 : 억원)
B17: 구분 | C17: 영업수지/영업수익 | G17: 영업이익
C18: 2022 | D18: 2023 | E18: 2024 | F18: 2025 | G18: 2022 | H18: 2023 | I18: 2024 | J18: 2025
B19: KS(관리) | C19: =C5/100 -> 10483.189 | D19: =D5/100 -> 8568.0528 | E19: =E5/100 -> 15926.71 | F19: =F5/100 -> 20933.49 | G19: =G5/100 -> 6235.64 | H19: =H5/100 -> 4433.54 | I19: =I5/100 -> 10599.22 | J19: =J5/100 -> 14219.28
B20: KS* | C20: =C6/100 -> 11088.4 | D20: =D6/100 -> 9201.7806 | E20: =E6/100 -> 16046.21 | F20: =F6/100 -> 20384.39 | G20: =G6/100 -> 6457.4522 | H20: =H6/100 -> 4723.8596 | I20: =I6/100 -> 10247.33 | J20: =J6/100 -> 13254.578
B21: KAM | C21: =C7/100 -> 806.24359 | D21: =D7/100 -> 793.68868 | E21: =E7/100 -> 849.54286 | F21: =F7/100 -> 1216.568 | G21: =G7/100 -> 272.55369 | H21: =H7/100 -> 227.12705 | I21: =I7/100 -> 228.67231 | J21: =J7/100 -> 500.4903
B22: KSB* | C22: =C8/100 -> 998.66895 | D22: =D8/100 -> 737.63656 | E22: =E8/100 -> 802.51968 | F22: =F8/100 -> 844.11386 | G22: =G8/100 -> 456.0672 | H22: =H8/100 -> 25.256544 | I22: =I8/100 -> 48.313713 | J22: =J8/100 -> 52.730288
B23: KYSB* | C23: =C9/100 -> 683.05342 | D23: =D9/100 -> 516.16427 | E23: =E9/100 -> 637.40058 | F23: =F9/100 -> 602.92332 | G23: =G9/100 -> 268.66043 | H23: =H9/100 -> -50.204271 | I23: =I9/100 -> -344.67315 | J23: =J9/100 -> -96.675604
B24: KI | C24: =C10/100 -> 98.570659 | D24: =D10/100 -> 146.4229 | E24: =E10/100 -> 172.99997 | F24: =F10/100 -> 255.07803 | G24: =G10/100 -> 25.07822 | H24: =H10/100 -> 33.185674 | I24: =I10/100 -> 67.249392 | J24: =J10/100 -> 145.84159
B25: KPE | C25: =C11/100 -> 53.313382 | D25: =D11/100 -> 128.98711 | E25: =E11/100 -> 85.008147 | F25: =F11/100 -> 79.58644 | G25: =G11/100 -> -126.96756 | H25: =H11/100 -> 50.891688 | I25: =I11/100 -> -4.2064939 | J25: =J11/100 -> 12.003748
B26: KC* | C26: =C12/100 -> 726.46248 | D26: =D12/100 -> 574.9326 | E26: =E12/100 -> 577.07662 | F26: =F12/100 -> 941.2242 | G26: =G12/100 -> 430.77642 | H26: =H12/100 -> 334.76984 | I26: =I12/100 -> 405.16306 | J26: =J12/100 -> 730.22151
B27: KFI(연결) | C27: =C13/100 -> 441.56901 | D27: =D13/100 -> 487.47495 | E27: =E13/100 -> 943.20006 | F27: =F13/100 -> 1404.2696 | G27: =G13/100 -> 120.24423 | H27: =H13/100 -> 106.16428 | I27: =I13/100 -> 165.14191 | J27: =J13/100 -> 255.86295
A28: KS(관리) | B28: 합계 | C28: =SUM(C21:C27,C19) -> 14291.07 | D28: =SUM(D21:D27,D19) -> 11953.36 | E28: =SUM(E21:E27,E19) -> 19994.458 | F28: =SUM(F21:F27,F19) -> 26277.253 | G28: =SUM(G21:G27,G19) -> 7682.0526 | H28: =SUM(H21:H27,H19) -> 5160.7308 | I28: =SUM(I21:I27,I19) -> 11164.881 | J28: =SUM(J21:J27,J19) -> 15819.755
B29: (*)영업수지
